<?xml version="1.0" encoding="utf-8"?>
<!-- This URDF was automatically created by SolidWorks to URDF Exporter! Originally created by Stephen Brawner (brawner@gmail.com) 
     Commit Version: 1.5.0-0-g9aa0fdb  Build Version: 1.5.7004.21443
     For more information, please see http://wiki.ros.org/sw_urdf_exporter -->
<robot
  name="Robotic_Arm">
  <link
    name="base_link">
    <inertial>
      <origin
        xyz="0.077471 -0.13294 0.11201"
        rpy="0 0 0" />
      <mass
        value="0.74796" />
      <inertia
        ixx="0.0022573"
        ixy="2.2339E-07"
        ixz="-8.1079E-08"
        iyy="0.0022579"
        iyz="-1.057E-07"
        izz="0.0039789" />
    </inertial>
    <visual>
      <origin
        xyz="0 0 0"
        rpy="0 0 0" />
      <geometry>
        <mesh
          filename="package://Robotic_Arm/meshes/base_link.STL" />
      </geometry>
      <material
        name="">
        <color
          rgba="0.79216 0.81961 0.93333 1" />
      </material>
    </visual>
    <collision>
      <origin
        xyz="0 0 0"
        rpy="0 0 0" />
      <geometry>
        <mesh
          filename="package://Robotic_Arm/meshes/base_link.STL" />
      </geometry>
    </collision>
  </link>
  <link
    name="arm_link_1">
    <inertial>
      <origin
        xyz="-0.0023986 0.021961 -0.00036542"
        rpy="0 0 0" />
      <mass
        value="0.44911" />
      <inertia
        ixx="0.00052376"
        ixy="1.1533E-09"
        ixz="-4.7849E-08"
        iyy="0.0011151"
        iyz="2.7992E-10"
        izz="0.00072274" />
    </inertial>
    <visual>
      <origin
        xyz="0 0 0"
        rpy="0 0 0" />
      <geometry>
        <mesh
          filename="package://Robotic_Arm/meshes/arm_link_1.STL" />
      </geometry>
      <material
        name="">
        <color
          rgba="0.79216 0.81961 0.93333 1" />
      </material>
    </visual>
    <collision>
      <origin
        xyz="0 0 0"
        rpy="0 0 0" />
      <geometry>
        <mesh
          filename="package://Robotic_Arm/meshes/arm_link_1.STL" />
      </geometry>
    </collision>
  </link>
  <joint
    name="arm_joint_1"
    type="continuous">
    <origin
      xyz="0.077663 -0.13275 0.16758"
      rpy="1.5708 0 0" />
    <parent
      link="base_link" />
    <child
      link="arm_link_1" />
    <axis
      xyz="0 1 0" />
    <limit
      lower="0"
      upper="3.14"
      effort="0"
      velocity="0" />
    <safety_controller
      k_velocity="0" />
  </joint>
  <link
    name="arm_link_2">
    <inertial>
      <origin
        xyz="-0.000500576888316895 0.192519116267856 -0.000265676079619553"
        rpy="0 0 0" />
      <mass
        value="0.421933647074247" />
      <inertia
        ixx="0.00119101878063656"
        ixy="-9.38571195847501E-08"
        ixz="-3.61118369829335E-07"
        iyy="0.000165865664319786"
        iyz="-8.58458961831822E-07"
        izz="0.00112242532449343" />
    </inertial>
    <visual>
      <origin
        xyz="0 0 0"
        rpy="0 0 0" />
      <geometry>
        <mesh
          filename="package://Robotic_Arm/meshes/arm_link_2.STL" />
      </geometry>
      <material
        name="">
        <color
          rgba="0.752941176470588 0.752941176470588 0.752941176470588 1" />
      </material>
    </visual>
    <collision>
      <origin
        xyz="0 0 0"
        rpy="0 0 0" />
      <geometry>
        <mesh
          filename="package://Robotic_Arm/meshes/arm_link_2.STL" />
      </geometry>
    </collision>
  </link>
  <joint
    name="arm_joint_2"
    type="continuous">
    <origin
      xyz="-0.0023104 0.032 -0.00054816"
      rpy="-1.5708 -1.3894 1.5708" />
    <parent
      link="arm_link_1" />
    <child
      link="arm_link_2" />
    <axis
      xyz="0 0 1" />
    <safety_controller
      k_velocity="0" />
  </joint>
  <link
    name="arm_link_3">
    <inertial>
      <origin
        xyz="0.00088882 0.15812 0.00071071"
        rpy="0 0 0" />
      <mass
        value="0.25828" />
      <inertia
        ixx="0.00027832"
        ixy="-8.812E-07"
        ixz="-1.4423E-11"
        iyy="5.4616E-05"
        iyz="-8.6935E-09"
        izz="0.00029095" />
    </inertial>
    <visual>
      <origin
        xyz="0 0 0"
        rpy="0 0 0" />
      <geometry>
        <mesh
          filename="package://Robotic_Arm/meshes/arm_link_3.STL" />
      </geometry>
      <material
        name="">
        <color
          rgba="0.79216 0.81961 0.93333 1" />
      </material>
    </visual>
    <collision>
      <origin
        xyz="0 0 0"
        rpy="0 0 0" />
      <geometry>
        <mesh
          filename="package://Robotic_Arm/meshes/arm_link_3.STL" />
      </geometry>
    </collision>
  </link>
  <joint
    name="arm_joint_3"
    type="continuous">
    <origin
      xyz="-0.0011 0.391 0.0013878"
      rpy="2.5049 -1.5708 0" />
    <parent
      link="arm_link_2" />
    <child
      link="arm_link_3" />
    <axis
      xyz="1 0 0" />
    <safety_controller
      k_velocity="0" />
  </joint>
  <link
    name="arm_link_4">
    <inertial>
      <origin
        xyz="0.00043251 0.065624 0.00078915"
        rpy="0 0 0" />
      <mass
        value="0.059133" />
      <inertia
        ixx="1.4968E-05"
        ixy="4.3637E-13"
        ixz="1.8275E-07"
        iyy="1.725E-05"
        iyz="-6.5009E-09"
        izz="1.5087E-05" />
    </inertial>
    <visual>
      <origin
        xyz="0 0 0"
        rpy="0 0 0" />
      <geometry>
        <mesh
          filename="package://Robotic_Arm/meshes/arm_link_4.STL" />
      </geometry>
      <material
        name="">
        <color
          rgba="0.79216 0.81961 0.93333 1" />
      </material>
    </visual>
    <collision>
      <origin
        xyz="0 0 0"
        rpy="0 0 0" />
      <geometry>
        <mesh
          filename="package://Robotic_Arm/meshes/arm_link_4.STL" />
      </geometry>
    </collision>
  </link>
  <joint
    name="arm_joint_4"
    type="continuous">
    <origin
      xyz="0.0034 0.2704 0.0011"
      rpy="0.63673 0 0" />
    <parent
      link="arm_link_3" />
    <child
      link="arm_link_4" />
    <axis
      xyz="1 0 0" />
    <safety_controller
      k_velocity="0" />
  </joint>
  <link
    name="arm_link_end">
    <inertial>
      <origin
        xyz="-7.7521E-10 0.012073 0.03756"
        rpy="0 0 0" />
      <mass
        value="0.0085149" />
      <inertia
        ixx="6.9141E-06"
        ixy="1.3475E-14"
        ixz="1.7911E-13"
        iyy="8.6264E-06"
        iyz="-2.0833E-06"
        izz="4.4015E-06" />
    </inertial>
    <visual>
      <origin
        xyz="0 0 0"
        rpy="0 0 0" />
      <geometry>
        <mesh
          filename="package://Robotic_Arm/meshes/arm_link_end.STL" />
      </geometry>
      <material
        name="">
        <color
          rgba="0.79216 0.81961 0.93333 1" />
      </material>
    </visual>
    <collision>
      <origin
        xyz="0 0 0"
        rpy="0 0 0" />
      <geometry>
        <mesh
          filename="package://Robotic_Arm/meshes/arm_link_end.STL" />
      </geometry>
    </collision>
  </link>
  <joint
    name="arm_joint_end"
    type="continuous">
    <origin
      xyz="0.00325 0.061354 0.032315"
      rpy="-1.0865 0 0" />
    <parent
      link="arm_link_4" />
    <child
      link="arm_link_end" />
    <axis
      xyz="1 0 0" />
    <safety_controller
      k_velocity="0" />
  </joint>
</robot>