<?xml version="1.0" encoding="utf-8"?>
<!-- This URDF was automatically created by SolidWorks to URDF Exporter! Originally created by Stephen Brawner (brawner@gmail.com) 
     Commit Version: 1.5.0-0-g9aa0fdb  Build Version: 1.5.7004.21443
     For more information, please see http://wiki.ros.org/sw_urdf_exporter -->
<robot
  name="Robotic_Arm">

  <link
    name="arm_link_1">
    <inertial>
      <origin
        xyz="-0.0023986 0.021961 -0.00036542"
        rpy="0 0 0" />
      <mass
        value="0.44911" />
      <inertia
        ixx="0.00052376"
        ixy="1.1533E-09"
        ixz="-4.7849E-08"
        iyy="0.0011151"
        iyz="2.7992E-10"
        izz="0.00072274" />
    </inertial>
    <visual>
      <origin
        xyz="0 0 0"
        rpy="0 0 0" />
      <geometry>
        <mesh
          filename="package://Robotic_Arm/meshes/arm_link_1.STL" />
      </geometry>
      <material
        name="">
        <color
          rgba="0.79216 0.81961 0.93333 1" />
      </material>
    </visual>
    <collision>
      <origin
        xyz="0 0 0"
        rpy="0 0 0" />
      <geometry>
        <mesh
          filename="package://Robotic_Arm/meshes/arm_link_1.STL" />
      </geometry>
    </collision>
  </link>
  <link
    name="arm_link_2">
    <inertial>
      <origin
        xyz="-0.00050058 0.19252 -0.00026568"
        rpy="0 0 0" />
      <mass
        value="0.42193" />
      <inertia
        ixx="0.001191"
        ixy="-9.3857E-08"
        ixz="-3.6112E-07"
        iyy="0.00016587"
        iyz="-8.5846E-07"
        izz="0.0011224" />
    </inertial>
    <visual>
      <origin
        xyz="0 0 0"
        rpy="0 0 0" />
      <geometry>
        <mesh
          filename="package://Robotic_Arm/meshes/arm_link_2.STL" />
      </geometry>
      <material
        name="">
        <color
          rgba="0.75294 0.75294 0.75294 1" />
      </material>
    </visual>
    <collision>
      <origin
        xyz="0 0 0"
        rpy="0 0 0" />
      <geometry>
        <mesh
          filename="package://Robotic_Arm/meshes/arm_link_2.STL" />
      </geometry>
    </collision>
  </link>
  <joint
    name="arm_joint_2"
    type="continuous">
    <origin
      xyz="-0.0023104 0.032 -0.00054816"
      rpy="-1.5708 -1.3894 1.5708" />
    <parent
      link="arm_link_1" />
    <child
      link="arm_link_2" />
    <axis
      xyz="0 0 1" />
    <safety_controller
      k_velocity="0" />
  </joint>
  <link
    name="arm_link_3">
    <inertial>
      <origin
        xyz="0.00088882 0.15812 0.00071071"
        rpy="0 0 0" />
      <mass
        value="0.25828" />
      <inertia
        ixx="0.00027832"
        ixy="-8.812E-07"
        ixz="-1.4423E-11"
        iyy="5.4616E-05"
        iyz="-8.6935E-09"
        izz="0.00029095" />
    </inertial>
    <visual>
      <origin
        xyz="0 0 0"
        rpy="0 0 0" />
      <geometry>
        <mesh
          filename="package://Robotic_Arm/meshes/arm_link_3.STL" />
      </geometry>
      <material
        name="">
        <color
          rgba="0.79216 0.81961 0.93333 1" />
      </material>
    </visual>
    <collision>
      <origin
        xyz="0 0 0"
        rpy="0 0 0" />
      <geometry>
        <mesh
          filename="package://Robotic_Arm/meshes/arm_link_3.STL" />
      </geometry>
    </collision>
  </link>
  <joint
    name="arm_joint_3"
    type="continuous">
    <origin
      xyz="-0.0011 0.391 0.0013878"
      rpy="2.5049 -1.5708 0" />
    <parent
      link="arm_link_2" />
    <child
      link="arm_link_3" />
    <axis
      xyz="1 0 0" />
    <safety_controller
      k_velocity="0" />
  </joint>
  <link
    name="arm_link_4">
    <inertial>
      <origin
        xyz="0.00043251 0.065624 0.00078915"
        rpy="0 0 0" />
      <mass
        value="0.059133" />
      <inertia
        ixx="1.4968E-05"
        ixy="4.3637E-13"
        ixz="1.8275E-07"
        iyy="1.725E-05"
        iyz="-6.5009E-09"
        izz="1.5087E-05" />
    </inertial>
    <visual>
      <origin
        xyz="0 0 0"
        rpy="0 0 0" />
      <geometry>
        <mesh
          filename="package://Robotic_Arm/meshes/arm_link_4.STL" />
      </geometry>
      <material
        name="">
        <color
          rgba="0.79216 0.81961 0.93333 1" />
      </material>
    </visual>
    <collision>
      <origin
        xyz="0 0 0"
        rpy="0 0 0" />
      <geometry>
        <mesh
          filename="package://Robotic_Arm/meshes/arm_link_4.STL" />
      </geometry>
    </collision>
  </link>
  <joint
    name="arm_joint_4"
    type="continuous">
    <origin
      xyz="0.0034 0.2704 0.0011"
      rpy="0.63673 0 0" />
    <parent
      link="arm_link_3" />
    <child
      link="arm_link_4" />
    <axis
      xyz="1 0 0" />
    <safety_controller
      k_velocity="0" />
  </joint>
  <link
    name="arm_link_end">
    <inertial>
      <origin
        xyz="0.030016 -0.023618 0.0143"
        rpy="0 0 0" />
      <mass
        value="0.0085149" />
      <inertia
        ixx="3.6005E-06"
        ixy="5.6076E-07"
        ixz="-1.6478E-13"
        iyy="9.4274E-06"
        iyz="7.1464E-14"
        izz="6.9141E-06" />
    </inertial>
    <visual>
      <origin
        xyz="0 0 0"
        rpy="0 0 0" />
      <geometry>
        <mesh
          filename="package://Robotic_Arm/meshes/arm_link_end.STL" />
      </geometry>
      <material
        name="">
        <color
          rgba="0.79216 0.81961 0.93333 1" />
      </material>
    </visual>
    <collision>
      <origin
        xyz="0 0 0"
        rpy="0 0 0" />
      <geometry>
        <mesh
          filename="package://Robotic_Arm/meshes/arm_link_end.STL" />
      </geometry>
    </collision>
  </link>
  <joint
    name="arm_joint_end"
    type="continuous">
    <origin
      xyz="0.01755 0.0702 0.0155"
      rpy="-1.5708 0 1.5708" />
    <parent
      link="arm_link_4" />
    <child
      link="arm_link_end" />
    <axis
      xyz="0 0 1" />
    <safety_controller
      k_velocity="0" />
  </joint>
</robot>