<?xml version="1.0" encoding="utf-8"?>
<!-- This URDF was automatically created by SolidWorks to URDF Exporter! Originally created by Stephen Brawner (brawner@gmail.com) 
     Commit Version: 1.5.0-0-g9aa0fdb  Build Version: 1.5.7004.21443
     For more information, please see http://wiki.ros.org/sw_urdf_exporter -->
<robot
  name="Robotic_Arm">
  <link
    name="base_link">
    <inertial>
      <origin
        xyz="0.077471 -0.13294 0.11201"
        rpy="0 0 0" />
      <mass
        value="0.74796" />
      <inertia
        ixx="0.0022573"
        ixy="2.2339E-07"
        ixz="-8.1079E-08"
        iyy="0.0022579"
        iyz="-1.057E-07"
        izz="0.0039789" />
    </inertial>
    <visual>
      <origin
        xyz="0 0 0"
        rpy="0 0 0" />
      <geometry>
        <mesh
          filename="package://Robotic_Arm/meshes/base_link.STL" />
      </geometry>
      <material
        name="">
        <color
          rgba="0.79216 0.81961 0.93333 1" />
      </material>
    </visual>
    <collision>
      <origin
        xyz="0 0 0"
        rpy="0 0 0" />
      <geometry>
        <mesh
          filename="package://Robotic_Arm/meshes/base_link.STL" />
      </geometry>
    </collision>
  </link>
  <link
    name="arm_link_1">
    <inertial>
      <origin
        xyz="-0.0023986 0.021961 -0.00036542"
        rpy="0 0 0" />
      <mass
        value="0.44911" />
      <inertia
        ixx="0.00052376"
        ixy="1.1533E-09"
        ixz="-4.7849E-08"
        iyy="0.0011151"
        iyz="2.7992E-10"
        izz="0.00072274" />
    </inertial>
    <visual>
      <origin
        xyz="0 0 0"
        rpy="0 0 0" />
      <geometry>
        <mesh
          filename="package://Robotic_Arm/meshes/arm_link_1.STL" />
      </geometry>
      <material
        name="">
        <color
          rgba="0.79216 0.81961 0.93333 1" />
      </material>
    </visual>
    <collision>
      <origin
        xyz="0 0 0"
        rpy="0 0 0" />
      <geometry>
        <mesh
          filename="package://Robotic_Arm/meshes/arm_link_1.STL" />
      </geometry>
    </collision>
  </link>
  <joint
    name="arm_joint_1"
    type="continuous">
    <origin
      xyz="0.077663 -0.13275 0.16758"
      rpy="1.5708 0 0" />
    <parent
      link="base_link" />
    <child
      link="arm_link_1" />
    <axis
      xyz="0 1 0" />
    <limit
      lower="0"
      upper="3.14"
      effort="0"
      velocity="0" />
    <safety_controller
      k_velocity="0" />
  </joint>
  <link
    name="arm_link_2">
    <inertial>
      <origin
        xyz="-0.000500576888321891 0.192519116267857 -0.000265676079625202"
        rpy="0 0 0" />
      <mass
        value="0.421933647074247" />
      <inertia
        ixx="0.00119101878063656"
        ixy="-9.38571195847433E-08"
        ixz="-3.61118369829338E-07"
        iyy="0.000165865664319786"
        iyz="-8.58458961831791E-07"
        izz="0.00112242532449343" />
    </inertial>
    <visual>
      <origin
        xyz="0 0 0"
        rpy="0 0 0" />
      <geometry>
        <mesh
          filename="package://Robotic_Arm/meshes/arm_link_2.STL" />
      </geometry>
      <material
        name="">
        <color
          rgba="0.752941176470588 0.752941176470588 0.752941176470588 1" />
      </material>
    </visual>
    <collision>
      <origin
        xyz="0 0 0"
        rpy="0 0 0" />
      <geometry>
        <mesh
          filename="package://Robotic_Arm/meshes/arm_link_2.STL" />
      </geometry>
    </collision>
  </link>
  <joint
    name="arm_joint_2"
    type="continuous">
    <origin
      xyz="-0.0023104 0.032 -0.00054816"
      rpy="-1.5708 -1.3894 1.5708" />
    <parent
      link="arm_link_1" />
    <child
      link="arm_link_2" />
    <axis
      xyz="0 0 1" />
    <safety_controller
      k_velocity="0" />
  </joint>
</robot>